Workbook
Name Slicer_Category: #N/A
Name Slicer_Product: #N/A
Name Slicer_Region: #N/A
Name Slicer_Sales_Rep: #N/A

Sheet Dashboard

Sheet Pivot Table
A3: Region | B3: Sum of Total Sale
A4: Badulla | B4: 18509000
A5: Colombo | B5: 19489500
A6: Galle | B6: 12867500
A7: Jaffna | B7: 15719000
A8: Kandy | B8: 14296500
A9: Kurunegala | B9: 14848500
A10: Matara | B10: 13574500
A11: Negombo | B11: 16583000
A12: Grand Total | B12: 125887500
A18: Product | B18: Sum of Total Sale
A19: Laptop | B19: 51600000
A20: Mobile | B20: 28720000
A21: Monitor | B21: 16860000
A22: Printer | B22: 16110000
A23: SSD | B23: 5364000
A24: Webcam | B24: 2584000
A25: Headphones | B25: 2114000
A26: Keyboard | B26: 1270000
A27: Mouse | B27: 667500
A28: USB | B28: 598000
A29: Grand Total | B29: 125887500
A32: Product | B32: Sum of Total Sale
A33: January | B33: 8555500
A34: February | B34: 9661500
A35: March | B35: 15163500
A36: April | B36: 11291000
A37: May | B37: 8353000
A38: June | B38: 12127500
A39: July | B39: 12340000
A40: August | B40: 6969500
A41: September | B41: 8537000
A42: October | B42: 11161500
A43: November | B43: 11384000
A44: December | B44: 10343500
A45: Grand Total | B45: 125887500
A48: Product | B48: Sales | C48: Total Profit
A49: Dilshan | B49: 16171000 | C49: 3255500
A50: Kavinda | B50: 14685500 | C50: 3009400
A51: Shehan | B51: 13968000 | C51: 2844000
...

Sheet Orders Data
A1: OrderID | B1: Date | C1: Customer | D1: Region | E1: Product | F1: Qty | G1: Unit Price | H1: Sales Rep | I1: Category | J1: Cost Price | K1: Brand | L1: Total Sale | M1: Total Cost | N1: Profit | O1: Profit Margin %
A2: O0001 | B2: 2026-06-11 | C2: Customer 57 | D2: Matara | E2: Laptop | F2: 3 | G2: 150000 | H2: Nuwan | I2: =_xlfn.XLOOKUP(E2,'Products Master'!A:A,'Products Master'!B:B) -> Electronics | J2: =_xlfn.XLOOKUP(E2,'Products Master'!A:A,'Products Master'!C:C) -> 120000 | K2: =_xlfn.XLOOKUP(E2,'Products Master'!A:A,'Products Master'!D:D) -> Dell | L2: =F2*G2 -> 450000 | M2: =F2*J2 -> 360000 | N2: =L2-M2 -> 90000 | O2: =N2/L2 -> 0.2
A3: O0002 | B3: 2026-05-14 | C3: Customer 33 | D3: Jaffna | E3: Printer | F3: 4 | G3: 45000 | H3: Kasun | I3: =_xlfn.XLOOKUP(E3,'Products Master'!A:A,'Products Master'!B:B) -> Electronics | J3: =_xlfn.XLOOKUP(E3,'Products Master'!A:A,'Products Master'!C:C) -> 35000 | K3: =_xlfn.XLOOKUP(E3,'Products Master'!A:A,'Products Master'!D:D) -> HP | L3: =F3*G3 -> 180000 | M3: =F3*J3 -> 140000 | N3: =L3-M3 -> 40000 | O3: =N3/L3 -> 0.22222222
A4: O0003 | B4: 2026-10-28 | C4: Customer 36 | D4: Colombo | E4: Mouse | F4: 2 | G4: 2500 | H4: Kavinda | I4: =_xlfn.XLOOKUP(E4,'Products Master'!A:A,'Products Master'!B:B) -> Accessories | J4: =_xlfn.XLOOKUP(E4,'Products Master'!A:A,'Products Master'!C:C) -> 1500 | K4: =_xlfn.XLOOKUP(E4,'Products Master'!A:A,'Products Master'!D:D) -> Logitech | L4: =F4*G4 -> 5000 | M4: =F4*J4 -> 3000 | N4: =L4-M4 -> 2000 | O4: =N4/L4 -> 0.4
A5: O0004 | B5: 2026-04-06 | C5: Customer 32 | D5: Badulla | E5: Mouse | F5: 5 | G5: 2500 | H5: Tharindu | I5: =_xlfn.XLOOKUP(E5,'Products Master'!A:A,'Products Master'!B:B) -> Accessories | J5: =_xlfn.XLOOKUP(E5,'Products Master'!A:A,'Products Master'!C:C) -> 1500 | K5: =_xlfn.XLOOKUP(E5,'Products Master'!A:A,'Products Master'!D:D) -> Logitech | L5: =F5*G5 -> 12500 | M5: =F5*J5 -> 7500 | N5: =L5-M5 -> 5000 | O5: =N5/L5 -> 0.4
A6: O0005 | B6: 2026-12-06 | C6: Customer 24 | D6: Kandy | E6: USB | F6: 3 | G6: 2000 | H6: Pasindu | I6: =_xlfn.XLOOKUP(E6,'Products Master'!A:A,'Products Master'!B:B) -> Storage | J6: =_xlfn.XLOOKUP(E6,'Products Master'!A:A,'Products Master'!C:C) -> 1200 | K6: =_xlfn.XLOOKUP(E6,'Products Master'!A:A,'Products Master'!D:D) -> SanDisk | L6: =F6*G6 -> 6000 | M6: =F6*J6 -> 3600 | N6: =L6-M6 -> 2400 | O6: =N6/L6 -> 0.4
A7: O0006 | B7: 2026-06-18 | C7: Customer 38 | D7: Kandy | E7: Monitor | F7: 4 | G7: 60000 | H7: Dilshan | I7: =_xlfn.XLOOKUP(E7,'Products Master'!A:A,'Products Master'!B:B) -> Electronics | J7: =_xlfn.XLOOKUP(E7,'Products Master'!A:A,'Products Master'!C:C) -> 50000 | K7: =_xlfn.XLOOKUP(E7,'Products Master'!A:A,'Products Master'!D:D) -> LG | L7: =F7*G7 -> 240000 | M7: =F7*J7 -> 200000 | N7: =L7-M7 -> 40000 | O7: =N7/L7 -> 0.16666667
A8: O0007 | B8: 2026-03-04 | C8: Customer 92 | D8: Kurunegala | E8: Printer | F8: 2 | G8: 45000 | H8: Tharindu | I8: =_xlfn.XLOOKUP(E8,'Products Master'!A:A,'Products Master'!B:B) -> Electronics | J8: =_xlfn.XLOOKUP(E8,'Products Master'!A:A,'Products Master'!C:C) -> 35000 | K8: =_xlfn.XLOOKUP(E8,'Products Master'!A:A,'Products Master'!D:D) -> HP | L8: =F8*G8 -> 90000 | M8: =F8*J8 -> 70000 | N8: =L8-M8 -> 20000 | O8: =N8/L8 -> 0.22222222
A9: O0008 | B9: 2026-03-26 | C9: Customer 25 | D9: Kurunegala | E9: Webcam | F9: 4 | G9: 9500 | H9: Nimesh | I9: =_xlfn.XLOOKUP(E9,'Products Master'!A:A,'Products Master'!B:B) -> Accessories | J9: =_xlfn.XLOOKUP(E9,'Products Master'!A:A,'Products Master'!C:C) -> 7000 | K9: =_xlfn.XLOOKUP(E9,'Products Master'!A:A,'Products Master'!D:D) -> Logitech | L9: =F9*G9 -> 38000 | M9: =F9*J9 -> 28000 | N9: =L9-M9 -> 10000 | O9: =N9/L9 -> 0.26315789
A10: O0009 | B10: 2026-09-19 | C10: Customer 31 | D10: Kurunegala | E10: Headphones | F10: 2 | G10: 7000 | H10: Nuwan | I10: =_xlfn.XLOOKUP(E10,'Products Master'!A:A,'Products Master'!B:B) -> Accessories | J10: =_xlfn.XLOOKUP(E10,'Products Master'!A:A,'Products Master'!C:C) -> 5000 | K10: =_xlfn.XLOOKUP(E10,'Products Master'!A:A,'Products Master'!D:D) -> Sony | L10: =F10*G10 -> 14000 | M10: =F10*J10 -> 10000 | N10: =L10-M10 -> 4000 | O10: =N10/L10 -> 0.28571429
A11: O0010 | B11: 2026-10-20 | C11: Customer 53 | D11: Jaffna | E11: Mouse | F11: 1 | G11: 2500 | H11: Nuwan | I11: =_xlfn.XLOOKUP(E11,'Products Master'!A:A,'Products Master'!B:B) -> Accessories | J11: =_xlfn.XLOOKUP(E11,'Products Master'!A:A,'Products Master'!C:C) -> 1500 | K11: =_xlfn.XLOOKUP(E11,'Products Master'!A:A,'Products Master'!D:D) -> Logitech | L11: =F11*G11 -> 2500 | M11: =F11*J11 -> 1500 | N11: =L11-M11 -> 1000 | O11: =N11/L11 -> 0.4
A12: O0011 | B12: 2026-11-12 | C12: Customer 61 | D12: Matara | E12: Headphones | F12: 1 | G12: 7000 | H12: Nuwan | I12: =_xlfn.XLOOKUP(E12,'Products Master'!A:A,'Products Master'!B:B) -> Accessories | J12: =_xlfn.XLOOKUP(E12,'Products Master'!A:A,'Products Master'!C:C) -> 5000 | K12: =_xlfn.XLOOKUP(E12,'Products Master'!A:A,'Products Master'!D:D) -> Sony | L12: =F12*G12 -> 7000 | M12: =F12*J12 -> 5000 | N12: =L12-M12 -> 2000 | O12: =N12/L12 -> 0.28571429
A13: O0012 | B13: 2026-10-06 | C13: Customer 12 | D13: Jaffna | E13: Headphones | F13: 2 | G13: 7000 | H13: Nimesh | I13: =_xlfn.XLOOKUP(E13,'Products Master'!A:A,'Products Master'!B:B) -> Accessories | J13: =_xlfn.XLOOKUP(E13,'Products Master'!A:A,'Products Master'!C:C) -> 5000 | K13: =_xlfn.XLOOKUP(E13,'Products Master'!A:A,'Products Master'!D:D) -> Sony | L13: =F13*G13 -> 14000 | M13: =F13*J13 -> 10000 | N13: =L13-M13 -> 4000 | O13: =N13/L13 -> 0.28571429
... A1001: O1000 | B1001: 2026-07-17 | C1001: Customer 26 | D1001: Matara | E1001: Laptop | F1001: 2 | G1001: 150000 | H1001: Dilshan | I1001: =_xlfn.XLOOKUP(E1001,'Products Master'!A:A,'Products Master'!B:B) -> Electronics | J1001: =_xlfn.XLOOKUP(E1001,'Products Master'!A:A,'Products Master'!C:C) -> 120000 | K1001: =_xlfn.XLOOKUP(E1001,'Products Master'!A:A,'Products Master'!D:D) -> Dell | L1001: =F1001*G1001 -> 300000 | M1001: =F1001*J1001 -> 240000 | N1001: =L1001-M1001 -> 60000 | O1001: =N1001/L1001 -> 0.2

Sheet Products Master
A1: Product | B1: Category | C1: Cost Price | D1: Brand
A2: Laptop | B2: Electronics | C2: 120000 | D2: Dell
A3: Monitor | B3: Electronics | C3: 50000 | D3: LG
A4: Mouse | B4: Accessories | C4: 1500 | D4: Logitech
A5: Keyboard | B5: Accessories | C5: 3500 | D5: Logitech
A6: Headphones | B6: Accessories | C6: 5000 | D6: Sony
A7: Mobile | B7: Electronics | C7: 65000 | D7: Samsung
A8: Printer | B8: Electronics | C8: 35000 | D8: HP
A9: SSD | B9: Storage | C9: 12000 | D9: Kingston
A10: USB | B10: Storage | C10: 1200 | D10: SanDisk
A11: Webcam | B11: Accessories | C11: 7000 | D11: Logitech

Sheet Sales Rep Data
A1: Sales Rep | B1: Region | C1: Target
A2: Kavinda | B2: Matara | C2: 670217
A3: Nuwan | B3: Jaffna | C3: 342286
A4: Pasindu | B4: Badulla | C4: 679462
A5: Sachin | B5: Negombo | C5: 453761
A6: Amila | B6: Kandy | C6: 536866
A7: Dilshan | B7: Jaffna | C7: 486659
A8: Kasun | B8: Colombo | C8: 719021
A9: Tharindu | B9: Galle | C9: 783618
A10: Nimesh | B10: Galle | C10: 377369
A11: Shehan | B11: Matara | C11: 865126
